Workbook

Sheet Target_IES
A1: Project | B1: Does this present in source | C1: Customer | D1: Income | E1: Cost | F1: Profit Margin | G1: Time | H1: Start date | I1: End date | J1: Status
A2: Affiliate 20% | B2: =VLOOKUP(A2,Source!$AH:$AH,1,FALSE) -> Affiliate 20% | C2: Direct | D2: $48,321.73 | E2: $98.45 | F2: 99.8% | G2: 0:00 | H2: 10/03/2017 | I2: 10/03/2017 | J2: Not started
A3: All Star | B3: =VLOOKUP(A3,Source!$AH:$AH,1,FALSE) -> #N/A | C3: Direct | D3: $3,146.77 | E3: $0.00 | F3: 100% | G3: 0:00 | H3: 10/03/2017 | I3: 10/03/2017 | J3: Not started
A4: Blyth Education Travel | B4: =VLOOKUP(A4,Source!$AH:$AH,1,FALSE) -> #N/A | C4: Direct | D4: $17,886.40 | E4: $0.00 | F4: 100% | G4: 0:00 | H4: 10/03/2017 | I4: 10/03/2017 | J4: Not started
A5: Cain Travel | B5: =VLOOKUP(A5,Source!$AH:$AH,1,FALSE) -> #N/A | C5: Direct | D5: $7,959.42 | E5: $0.00 | F5: 100% | G5: 0:00 | H5: 10/03/2017 | I5: 10/03/2017 | J5: Not started
A6: Chrysalis Event Hawaii - FIT | B6: =VLOOKUP(A6,Source!$AH:$AH,1,FALSE) -> Chrysalis Event Hawaii - FIT | C6: Chrysalis Events | D6: $19,595.67 | E6: $0.00 | F6: 100% | G6: 0:00 | J6: Not started
A7: Chrysalis Events Hawaii | B7: =VLOOKUP(A7,Source!$AH:$AH,1,FALSE) -> Chrysalis Events Hawaii | C7: Chrysalis Events | D7: $290,876.93 | E7: $61.94 | F7: 100% | G7: 0:00 | J7: Not started
A8: Crossing Boundaries | B8: =VLOOKUP(A8,Source!$AH:$AH,1,FALSE) -> Crossing Boundaries | C8: Affiliate 15% | D8: $47,140.78 | E8: $0.00 | F8: 100% | G8: 0:00 | H8: 10/03/2017 | I8: 10/03/2017 | J8: Not started
A9: DeSilva Meetings Consultants FIT | B9: =VLOOKUP(A9,Source!$AH:$AH,1,FALSE) -> #N/A | C9: Desilva Meetings Consultants | D9: $37,183.80 | E9: $6.42 | F9: 100% | G9: 0:00 | J9: Not started
A10: Desilva Meetings Consultants- Groups | B10: =VLOOKUP(A10,Source!$AH:$AH,1,FALSE) -> Desilva Meetings Consultants- Groups | C10: Desilva Meetings Consultants | D10: $269,177.46 | E10: $0.00 | F10: 100% | G10: 0:00 | J10: Not started
A11: DoTerra | B11: =VLOOKUP(A11,Source!$AH:$AH,1,FALSE) -> DoTerra | C11: Direct | D11: $16,000.00 | E11: $0.00 | F11: 100% | G11: 0:00 | H11: 10/03/2017 | I11: 10/03/2017 | J11: Not started
A12: Fei Wang | B12: =VLOOKUP(A12,Source!$AH:$AH,1,FALSE) -> #N/A | C12: American Excursionist {Customer} | D12: $3,710.33 | E12: $0.00 | F12: 100% | G12: 0:00 | J12: Not started
A13: FIT | B13: =VLOOKUP(A13,Source!$AH:$AH,1,FALSE) -> FIT | C13: MC&A | D13: $167,302.53 | E13: $0.00 | F13: 100% | G13: 0:00 | J13: Not started
A14: Frosch Travel | B14: =VLOOKUP(A14,Source!$AH:$AH,1,FALSE) -> Frosch Travel | C14: Direct | D14: $6,188.48 | E14: $41.94 | F14: 99.3% | G14: 0:00 | H14: 10/03/2017 | I14: 10/03/2017 | J14: Not started
A15: Going Places Travel | B15: =VLOOKUP(A15,Source!$AH:$AH,1,FALSE) -> Going Places Travel | C15: Direct | D15: $12,527.09 | E15: $0.00 | F15: 100% | G15: 0:00 | H15: 10/03/2017 | I15: 10/03/2017 | J15: Not started
A16: Groups | B16: =VLOOKUP(A16,Source!$AH:$AH,1,FALSE) -> Groups | C16: MC&A | D16: $972,583.75 | E16: $869.03 | F16: 99.9% | G16: 0:00 | J16: Not started
A17: Hualalai Investors dba Four Seasons Reso | B17: =VLOOKUP(A17,Source!$AH:$AH,1,FALSE) -> Hualalai Investors dba Four Seasons Reso | C17: Four Seasons | D17: $926,719.50 | E17: $553.31 | F17: 99.9% | G17: 0:00 | J17: Not started
A18: Hualalai Investors Hotel dba Four Seasons | B18: =VLOOKUP(A18,Source!$AH:$AH,1,FALSE) -> Hualalai Investors Hotel dba Four Seasons | C18: Four Seasons | D18: $966,883.65 | E18: $0.00 | F18: 100% | G18: 0:00 | J18: Not started
A19: Island Partners Hawaii - FIT | B19: =VLOOKUP(A19,Source!$AH:$AH,1,FALSE) -> Island Partners Hawaii - FIT | C19: MC&A | D19: $158,227.44 | E19: $19.66 | F19: 100% | G19: 0:00 | J19: Not started
A20: Janet Newlon | B20: =VLOOKUP(A20,Source!$AH:$AH,1,FALSE) -> #N/A | C20: Exclusive Resorts. | D20: $2,270.16 | E20: $135.43 | F20: 94% | G20: 0:00 | J20: Not started
A21: Kathy Clarke's Meeting - Groups | B21: =VLOOKUP(A21,Source!$AH:$AH,1,FALSE) -> Kathy Clarke's Meeting - Groups | C21: Kathy Clarke's | D21: $242,929.15 | E21: $0.00 | F21: 100% | G21: 0:00 | J21: Not started
A22: MC&A - Groups | B22: =VLOOKUP(A22,Source!$AH:$AH,1,FALSE) -> MC&A - Groups | C22: MC&A | D22: $1,060,144.90 | E22: $2,964.87 | F22: 99.7% | G22: 0:00 | J22: Not started
A23: Nuba | B23: =VLOOKUP(A23,Source!$AH:$AH,1,FALSE) -> #N/A | C23: Direct | D23: $2,697.64 | E23: -$13.00 | F23: 100.5% | G23: 0:00 | H23: 10/03/2017 | I23: 10/03/2017 | J23: Not started
A24: Panache Destination Management - FIT | B24: =VLOOKUP(A24,Source!$AH:$AH,1,FALSE) -> #N/A | C24: Panache | D24: $6,262.39 | E24: $0.00 | F24: 100% | G24: 0:00 | J24: Not started
A25: Panache Destination Management - Groups | B25: =VLOOKUP(A25,Source!$AH:$AH,1,FALSE) -> #N/A | C25: Panache | D25: $490,238.41 | E25: $5,031.29 | F25: 99% | G25: 0:00 | J25: Not started
A26: Paradise Helicopters - Agency | B26: =VLOOKUP(A26,Source!$AH:$AH,1,FALSE) -> Paradise Helicopters - Agency | C26: Paradise Helicopters | D26: $548,868.16 | E26: $0.00 | F26: 100% | G26: 0:00 | H26: 09/16/2014 | I26: 09/16/2014 | J26: Not started
A27: Paradise Helicopters - Groups | B27: =VLOOKUP(A27,Source!$AH:$AH,1,FALSE) -> Paradise Helicopters - Groups | C27: Paradise Helicopters | D27: $131,445.44 | E27: $0.78 | F27: 100% | G27: 0:00 | J27: Not started
A28: Paradise Helicopters- Activity Desk | B28: =VLOOKUP(A28,Source!$AH:$AH,1,FALSE) -> #N/A | C28: Paradise Helicopters | D28: $147,512.39 | E28: $250.00 | F28: 99.8% | G28: 0:00 | H28: 09/16/2014 | I28: 09/16/2014 | J28: Not started
A29: Resilient Indigenous Leaders Network | B29: =VLOOKUP(A29,Source!$AH:$AH,1,FALSE) -> Resilient Indigenous Leaders Network | C29: Direct | D29: $36,397.06 | E29: $485.12 | F29: 98.7% | G29: 0:00 | H29: 10/03/2017 | I29: 10/03/2017 | J29: Not started
A30: Rockit Events | B30: =VLOOKUP(A30,Source!$AH:$AH,1,FALSE) -> Rockit Events | C30: Direct | D30: $10,055.31 | E30: $0.00 | F30: 100% | G30: 0:00 | H30: 06/20/2024 | J30: Not started
A31: SAP | B31: =VLOOKUP(A31,Source!$AH:$AH,1,FALSE) -> #N/A | C31: Weil & Associates-Groups | D31: $73,585.56 | E31: $500.00 | F31: 99.3% | G31: 0:00 | J31: Not started
A32: Taylor Family Limited Partnership | B32: =VLOOKUP(A32,Source!$AH:$AH,1,FALSE) -> #N/A | C32: Direct | D32: $8,100.00 | E32: $0.00 | F32: 100% | G32: 0:00 | H32: 10/03/2017 | I32: 10/03/2017 | J32: Not started
A33: The Wright Company | B33: =VLOOKUP(A33,Source!$AH:$AH,1,FALSE) -> The Wright Company | C33: Direct | D33: $9,117.54 | E33: $0.00 | F33: 100% | G33: 0:00 | H33: 10/03/2017 | I33: 10/03/2017 | J33: Not started
A34: TMG Hawaii - Groups | B34: =VLOOKUP(A34,Source!$AH:$AH,1,FALSE) -> #N/A | C34: TMG | D34: $206,029.62 | E34: $207.68 | F34: 99.9% | G34: 0:00 | J34: Not started
A35: University of Hawaii | B35: =VLOOKUP(A35,Source!$AH:$AH,1,FALSE) -> #N/A | C35: Direct | D35: $9,519.44 | E35: $0.00 | F35: 100% | G35: 0:00 | H35: 10/03/2017 | I35: 10/03/2017 | J35: Not started
A36: Victor Emanuel Nature Tours | B36: =VLOOKUP(A36,Source!$AH:$AH,1,FALSE) -> Victor Emanuel Nature Tours | C36: Direct | D36: $75,103.24 | E36: $0.00 | F36: 100% | G36: 0:00 | H36: 10/03/2017 | I36: 10/03/2017 | J36: Not started

Sheet Source
A1: Taxable | B1: BillAddr.Id | C1: BillAddr.Line1 | D1: BillAddr.Line2 | E1: BillAddr.Line3 | F1: BillAddr.City | G1: BillAddr.CountrySubDivisionCode | H1: BillAddr.PostalCode | I1: ShipAddr.Id | J1: ShipAddr.Line1 | K1: ShipAddr.Line2 | L1: ShipAddr.Line3 | M1: ShipAddr.City | N1: ShipAddr.CountrySubDivisionCode | O1: ShipAddr.PostalCode | P1: Job | Q1: BillWithParent | R1: Balance | S1: BalanceWithJobs | T1: CurrencyRef.value | U1: CurrencyRef.name | V1: PreferredDeliveryMethod | W1: IsProject | X1: ClientEntityId | Y1: domain | Z1: sparse | AA1: Id | AC1: SyncToken | AD1: MetaData.CreateTime | AE1: MetaData.LastUpdatedTime | AF1: FullyQualifiedName | AG1: Does present in target ies project | AH1: DisplayName | AI1: PrintOnCheckName | AJ1: Active | AK1: V4IDPseudonym | AL1: SalesTermRef.value | AM1: SalesTermRef.name | AN1: TaxExemptionReasonId | AO1: PrimaryEmailAddr.Address | AP1: Notes | AQ1: CustomerTypeRef.value | AR1: AlternatePhone.FreeFormNumber | AS1: BillAddr.Line4 | AT1: ShipAddr.Line4 | AU1: CompanyName | AV1: PrimaryPhone.FreeFormNumber | AW1: Fax.FreeFormNumber | AX1: GivenName | AY1: ParentRef.value | AZ1: Level | BA1: DefaultTaxCodeRef.value | BB1: PaymentMethodRef.value | BC1: FamilyName | BD1: BillAddr.Country | BE1: ShipAddr.Country | BF1: WebAddr.URI | BG1: Mobile.FreeFormNumber | BH1: MiddleName
A2: FALSE | B2: [NULL] | C2: [NULL] | D2: [NULL] | E2: [NULL] | F2: [NULL] | G2: [NULL] | H2: [NULL] | I2: [NULL] | J2: [NULL] | K2: [NULL] | L2: [NULL] | M2: [NULL] | N2: [NULL] | O2: [NULL] | P2: TRUE | Q2: TRUE | R2: 0 | S2: 0 | T2: USD | U2: United States Dollar | V2: Print | W2: TRUE | X2: 0 | Y2: QBO | Z2: FALSE | AA2: 19 | AC2: 6 | AD2: 2024-12-03T16:39:43-08:00 | AE2: 2025-05-06T15:02:13-07:00 | AF2: KMC&A:MC&A - Groups | AG2: =VLOOKUP(AH2,Target_IES!$A:$A,1,FALSE) -> MC&A - Groups | AH2: MC&A - Groups | AI2: MC&A - Groups | AJ2: TRUE | AK2: 0020516d2aa712cb344411b9baafd8daddc913 | AL2: 8 | AM2: Net 30 | AN2: 99 | AO2: accountingmca@mcahawaii.com, Lynnen_Kim@mcahawaii.com | AP2: Island Partners Hawaii_x000D_ 615 Piikoi Street, Suite 1000_x000D_ Honolulu, HI 96814_x000D_ Attn: Qian Wang AP_x000D_ 808-589-5548 act._x000D_ 808-394-2515_x000D_ Fax- 808-394-1735_x000D_ accountingmca@mcahawaii.com | AQ2: 593703 | AR2: [NULL] | AS2: [NULL] | AT2: [NULL] | AU2: MC&A | AV2: 808-589-5500 | AW2: [NULL] | AX2: [NULL] | AY2: 16 | AZ2: 1 | BA2: [NULL] | BB2: [NULL] | BC2: [NULL] | BD2: [NULL] | BE2: [NULL] | BF2: [NULL] | BG2: [NULL] | BH2: [NULL]
A3: FALSE | B3: 15 | C3: MC&A | D3: [NULL] | E3: [NULL] | F3: [NULL] | G3: [NULL] | H3: [NULL] | I3: 15 | J3: MC&A | K3: [NULL] | L3: [NULL] | M3: [NULL] | N3: [NULL] | O3: [NULL] | P3: TRUE | Q3: TRUE | R3: 0 | S3: 0 | T3: USD | U3: United States Dollar | V3: Print | W3: TRUE | X3: 0 | Y3: QBO | Z3: FALSE | AA3: 18 | AB3: =_xlfn.CONCAT("'",AA3,"'",",") -> '18', | AC3: 3 | AD3: 2024-12-03T16:39:43-08:00 | AE3: 2025-04-03T17:58:08-07:00 | AF3: KMC&A:MC&A - FIT | AG3: =VLOOKUP(AH3,Target_IES!$A:$A,1,FALSE) -> #N/A | AH3: MC&A - FIT | AI3: MC&A - FIT | AJ3: TRUE | AK3: 0020517357d20db9a74aae90c7fe15776b8af6 | AL3: 8 | AM3: Net 30 | AN3: 99 | AO3: accountingmca@mcahawaii.com | AP3: [NULL] | AQ3: 593694 | AR3: [NULL] | AS3: [NULL] | AT3: [NULL] | AU3: MC & A | AV3: 808-589-5500 | AW3: 808-589-5501 | AX3: [NULL] | AY3: 16 | AZ3: 1 | BA3: [NULL] | BB3: [NULL] | BC3: [NULL] | BD3: [NULL] | BE3: [NULL] | BF3: [NULL] | BG3: [NULL] | BH3: [NULL]
A4: FALSE | B4: [NULL] | C4: [NULL] | D4: [NULL] | E4: [NULL] | F4: [NULL] | G4: [NULL] | H4: [NULL] | I4: [NULL] | J4: [NULL] | K4: [NULL] | L4: [NULL] | M4: [NULL] | N4: [NULL] | O4: [NULL] | P4: TRUE | Q4: TRUE | R4: 0 | S4: 0 | T4: USD | U4: United States Dollar | V4: Print | W4: TRUE | X4: 0 | Y4: QBO | Z4: FALSE | AA4: 17 | AC4: 3 | AD4: 2024-12-03T16:39:43-08:00 | AE4: 2025-05-15T17:50:37-07:00 | AF4: KMC&A:Island Partners Hawaii - FIT | AG4: =VLOOKUP(AH4,Target_IES!$A:$A,1,FALSE) -> Island Partners Hawaii - FIT | AH4: Island Partners Hawaii - FIT | AI4: Island Partners Hawaii - FIT | AJ4: TRUE | AK4: 0020517cdeb64a53904e0a9f31a08ad799bbbf | AL4: 8 | AM4: Net 30 | AN4: 99 | AO4: lillianh@islandpartnershawaii.com | AP4: [NULL] | AQ4: 593703 | AR4: [NULL] | AS4: [NULL] | AT4: [NULL] | AU4: [NULL] | AV4: [NULL] | AW4: [NULL] | AX4: [NULL] | AY4: 16 | AZ4: 1 | BA4: [NULL] | BB4: [NULL] | BC4: [NULL] | BD4: [NULL] | BE4: [NULL] | BF4: [NULL] | BG4: [NULL] | BH4: [NULL]
A5: FALSE | B5: 25 | C5: Four Seasons Hotel | D5: P.O. Box 1269 | E5: [NULL] | F5: Kailua-Kona | G5: HI | H5: 96740 | I5: 25 | J5: Four Seasons Hotel | K5: P.O. Box 1269 | L5: [NULL] | M5: Kailua-Kona | N5: HI | O5: 96740 | P5: TRUE | Q5: TRUE | R5: 0 | S5: 0 | T5: USD | U5: United States Dollar | V5: Print | W5: TRUE | X5: 0 | Y5: QBO | Z5: FALSE | AA5: 37 | AC5: 3 | AD5: 2024-12-03T16:39:44-08:00 | AE5: 2025-09-08T15:13:08-07:00 | AF5: Four Seasons:Hualalai Investors Hotel dba Four Seasons | AG5: =VLOOKUP(AH5,Target_IES!$A:$A,1,FALSE) -> Hualalai Investors Hotel dba Four Seasons | AH5: Hualalai Investors Hotel dba Four Seasons | AI5: Hualalai Investors Hotel dba Four Seasons | AJ5: TRUE | AK5: 00205113c18926a8314cfc9305e414f19b5445 | AL5: 8 | AM5: Net 30 | AN5: 99 | AO5: james.cantyne@fourseasons.com | AP5: Wil Mazzarella- wil.mazzarella@fourseasons.com- 325-8142 | AQ5: 593695 | AR5: (808)325-8058 | AS5: [NULL] | AT5: [NULL] | AU5: [NULL] | AV5: [NULL] | AW5: [NULL] | AX5: [NULL] | AY5: 35 | AZ5: 1 | BA5: [NULL] | BB5: [NULL] | BC5: [NULL] | BD5: [NULL] | BE5: [NULL] | BF5: [NULL] | BG5: [NULL] | BH5: [NULL]
A6: FALSE | B6: 24 | C6: Four Seasons Resort | D6: P.O. Box 1269 | E6: [NULL] | F6: Kailua-Kona | G6: HI | H6: 96740 | I6: 24 | J6: Four Seasons Resort | K6: P.O. Box 1269 | L6: [NULL] | M6: Kailua-Kona | N6: HI | O6: 96740 | P6: TRUE | Q6: TRUE | R6: 0 | S6: 0 | T6: USD | U6: United States Dollar | V6: Print | W6: TRUE | X6: 0 | Y6: QBO | Z6: FALSE | AA6: 36 | AC6: 3 | AD6: 2024-12-03T16:39:44-08:00 | AE6: 2025-09-30T13:59:51-07:00 | AF6: Four Seasons:Hualalai Investors dba Four Seasons Reso | AG6: =VLOOKUP(AH6,Target_IES!$A:$A,1,FALSE) -> Hualalai Investors dba Four Seasons Reso | AH6: Hualalai Investors dba Four Seasons Reso | AI6: Hualalai Investors dba Four Seasons Reso | AJ6: TRUE | AK6: 00205136c5e9e38dc7431dadc0f7f1fe0d5344 | AL6: [NULL] | AM6: [NULL] | AN6: 99 | AO6: FSHInvoicesKona.ig@capgemini.com | AP6: Wil Mazzarella- wil.mazzarella@fourseasons.com- 325-8142 | AQ6: 593695 | AR6: (808)325-8058 | AS6: [NULL] | AT6: [NULL] | AU6: [NULL] | AV6: [NULL] | AW6: [NULL] | AX6: [NULL] | AY6: 35 | AZ6: 1 | BA6: [NULL] | BB6: [NULL] | BC6: [NULL] | BD6: [NULL] | BE6: [NULL] | BF6: [NULL] | BG6: [NULL] | BH6: [NULL]
A7: FALSE | B7: 22 | C7: Desilva Meeting Consultants | D7: PO Box 790271 | E7: [NULL] | F7: Paia | G7: HI | H7: 96779 | I7: 22 | J7: Desilva Meeting Consultants | K7: PO Box 790271 | L7: [NULL] | M7: Paia | N7: HI | O7: 96779 | P7: TRUE | Q7: TRUE | R7: 0 | S7: 0 | T7: USD | U7: United States Dollar | V7: Print | W7: TRUE | X7: 0 | Y7: QBO | Z7: FALSE | AA7: 30 | AC7: 3 | AD7: 2024-12-03T16:39:44-08:00 | AE7: 2025-07-28T12:51:11-07:00 | AF7: Desilva Meetings Consultants:Desilva Meetings Consultants- Groups | AG7: =VLOOKUP(AH7,Target_IES!$A:$A,1,FALSE) -> Desilva Meetings Consultants- Groups | AH7: Desilva Meetings Consultants- Groups | AI7: Desilva Meetings Consultants- Groups | AJ7: TRUE | AK7: 002051a526c719a8b94541aa7d8556dbdf424a | AL7: 8 | AM7: Net 30 | AN7: 99 | AO7: tj@desilvadmc.com, | AP7: [NULL] | AQ7: 593694 | AR7: [NULL] | AS7: [NULL] | AT7: [NULL] | AU7: [NULL] | AV7: 808) 575-5400 | AW7: (808) 579-5032 | AX7: [NULL] | AY7: 29 | AZ7: 1 | BA7: [NULL] | BB7: [NULL] | BC7: [NULL] | BD7: [NULL] | BE7: [NULL] | BF7: [NULL] | BG7: [NULL] | BH7: [NULL]
A8: FALSE | B8: [NULL] | C8: [NULL] | D8: [NULL] | E8: [NULL] | F8: [NULL] | G8: [NULL] | H8: [NULL] | I8: [NULL] | J8: [NULL] | K8: [NULL] | L8: [NULL] | M8: [NULL] | N8: [NULL] | O8: [NULL] | P8: TRUE | Q8: TRUE | R8: 0 | S8: 0 | T8: USD | U8: United States Dollar | V8: Print | W8: TRUE | X8: 0 | Y8: QBO | Z8: FALSE | AA8: 61 | AC8: 3 | AD8: 2024-12-03T16:39:46-08:00 | AE8: 2025-04-03T18:00:36-07:00 | AF8: Kathy Clarke's:Kathy Clarke's Meeting - Groups | AG8: =VLOOKUP(AH8,Target_IES!$A:$A,1,FALSE) -> Kathy Clarke's Meeting - Groups | AH8: Kathy Clarke's Meeting - Groups | AI8: Kathy Clarke's Meeting - Groups | AJ8: TRUE | AK8: 002051f98b68af9e8a46c48b07b9da610578b2 | AL8: 8 | AM8: Net 30 | AN8: 99 | AO8: Kathy@kathyclarkehawaii.com | AP8: [NULL] | AQ8: 593695 | AR8: [NULL] | AS8: [NULL] | AT8: [NULL] | AU8: [NULL] | AV8: [NULL] | AW8: [NULL] | AX8: [NULL] | AY8: 60 | AZ8: 1 | BA8: [NULL] | BB8: [NULL] | BC8: [NULL] | BD8: [NULL] | BE8: [NULL] | BF8: [NULL] | BG8: [NULL] | BH8: [NULL]
A9: FALSE | B9: 54 | C9: Island Partners | D9: [NULL] | E9: [NULL] | F9: [NULL] | G9: [NULL] | H9: [NULL] | I9: 54 | J9: Island Partners | K9: [NULL] | L9: [NULL] | M9: [NULL] | N9: [NULL] | O9: [NULL] | P9: TRUE | Q9: TRUE | R9: 0 | S9: 0 | T9: USD | U9: United States Dollar | V9: Print | W9: TRUE | X9: 0 | Y9: QBO | Z9: FALSE | AA9: 97 | AC9: 3 | AD9: 2024-12-03T16:39:49-08:00 | AE9: 2025-04-03T18:00:11-07:00 | AF9: MC&A:Island Partners Hawaii - FIT | AG9: =VLOOKUP(AH9,Target_IES!$A:$A,1,FALSE) -> Island Partners Hawaii - FIT | AH9: Island Partners Hawaii - FIT | AI9: Island Partners Hawaii - FIT | AJ9: TRUE | AK9: 002051e8ad3bb0043f428683870e6126f920fe | AL9: 8 | AM9: Net 30 | AN9: 99 | AO9: michellem@islandpartnershawaii.com | AP9: [NULL] | AQ9: 593695 | AR9: [NULL] | AS9: [NULL] | AT9: [NULL] | AU9: [NULL] | AV9: [NULL] | AW9: [NULL] | AX9: [NULL] | AY9: 94 | AZ9: 1 | BA9: [NULL] | BB9: [NULL] | BC9: [NULL] | BD9: [NULL] | BE9: [NULL] | BF9: [NULL] | BG9: [NULL] | BH9: [NULL]
A10: FALSE | B10: 53 | C10: MC&A Groups | D10: [NULL] | E10: [NULL] | F10: [NULL] | G10: [NULL] | H10: [NULL] | I10: 53 | J10: MC&A Groups | K10: [NULL] | L10: [NULL] | M10: [NULL] | N10: [NULL] | O10: [NULL] | P10: TRUE | Q10: TRUE | R10: 0 | S10: 0 | T10: USD | U10: United States Dollar | V10: Print | W10: TRUE | X10: 0 | Y10: QBO | Z10: FALSE | AA10: 96 | AC10: 7 | AD10: 2024-12-03T16:39:49-08:00 | AE10: 2025-06-23T15:26:36-07:00 | AF10: MC&A:Groups | AG10: =VLOOKUP(AH10,Target_IES!$A:$A,1,FALSE) -> Groups | AH10: Groups | AI10: Groups | AJ10: TRUE | AK10: 00205153ae0e4ab1a3437690a5aebe20ac692f | AL10: 8 | AM10: Net 30 | AN10: 99 | AO10: accountingmca@mcahawaii.com | AP10: [NULL] | AQ10: [NULL] | AR10: [NULL] | AS10: [NULL] | AT10: [NULL] | AU10: [NULL] | AV10: [NULL] | AW10: [NULL] | AX10: [NULL] | AY10: 94 | AZ10: 1 | BA10: [NULL] | BB10: [NULL] | BC10: [NULL] | BD10: [NULL] | BE10: [NULL] | BF10: [NULL] | BG10: [NULL] | BH10: [NULL]
A11: FALSE | B11: [NULL] | C11: [NULL] | D11: [NULL] | E11: [NULL] | F11: [NULL] | G11: [NULL] | H11: [NULL] | I11: [NULL] | J11: [NULL] | K11: [NULL] | L11: [NULL] | M11: [NULL] | N11: [NULL] | O11: [NULL] | P11: TRUE | Q11: TRUE | R11: 0 | S11: 0 | T11: USD | U11: United States Dollar | V11: Print | W11: TRUE | X11: 0 | Y11: QBO | Z11: FALSE | AA11: 95 | AC11: 5 | AD11: 2024-12-03T16:39:49-08:00 | AE11: 2025-04-04T13:30:17-07:00 | AF11: MC&A:FIT | AG11: =VLOOKUP(AH11,Target_IES!$A:$A,1,FALSE) -> FIT | AH11: FIT | AI11: FIT | AJ11: TRUE | AK11: 002051b62dc26221ee4dfa9693317d791dd2a9 | AL11: 8 | AM11: Net 30 | AN11: 99 | AO11: accountingmca@mcahawaii.com | AP11: [NULL] | AQ11: [NULL] | AR11: [NULL] | AS11: [NULL] | AT11: [NULL] | AU11: [NULL] | AV11: [NULL] | AW11: [NULL] | AX11: [NULL] | AY11: 94 | AZ11: 1 | BA11: [NULL] | BB11: [NULL] | BC11: [NULL] | BD11: [NULL] | BE11: [NULL] | BF11: [NULL] | BG11: [NULL] | BH11: [NULL]
A12: FALSE | B12: [NULL] | C12: [NULL] | D12: [NULL] | E12: [NULL] | F12: [NULL] | G12: [NULL] | H12: [NULL] | I12: [NULL] | J12: [NULL] | K12: [NULL] | L12: [NULL] | M12: [NULL] | N12: [NULL] | O12: [NULL] | P12: TRUE | Q12: TRUE | R12: 0 | S12: 0 | T12: USD | U12: United States Dollar | V12: Print | W12: TRUE | X12: 0 | Y12: QBO | Z12: FALSE | AA12: 109 | AC12: 3 | AD12: 2024-12-03T16:39:50-08:00 | AE12: 2025-04-03T18:00:32-07:00 | AF12: Paradise Helicopters:Paradise Helicopters - Groups | AG12: =VLOOKUP(AH12,Target_IES!$A:$A,1,FALSE) -> Paradise Helicopters - Groups | AH12: Paradise Helicopters - Groups | AI12: Paradise Helicopters - Groups | AJ12: TRUE | AK12: 00205162e031d31f5547059394f890432835a5 | AL12: 8 | AM12: Net 30 | AN12: 99 | AO12: [NULL] | AP12: [NULL] | AQ12: 593695 | AR12: [NULL] | AS12: [NULL] | AT12: [NULL] | AU12: Paradise Helicopters-Groups | AV12: [NULL] | AW12: [NULL] | AX12: [NULL] | AY12: 107 | AZ12: 1 | BA12: [NULL] | BB12: [NULL] | BC12: [NULL] | BD12: [NULL] | BE12: [NULL] | BF12: [NULL] | BG12: [NULL] | BH12: [NULL]
A13: FALSE | B13: 60 | C13: PO Box 5371 | D13: [NULL] | E13: [NULL] | F13: Kailua Kona | G13: HI | H13: 96745 | I13: 60 | J13: PO Box 5371 | K13: [NULL] | L13: [NULL] | M13: Kailua Kona | N13: HI | O13: 96745 | P13: TRUE | Q13: TRUE | R13: 0 | S13: 0 | T13: USD | U13: United States Dollar | V13: Print | W13: TRUE | X13: 0 | Y13: QBO | Z13: FALSE | AA13: 108 | AC13: 3 | AD13: 2024-12-03T16:39:50-08:00 | AE13: 2025-04-03T18:00:27-07:00 | AF13: Paradise Helicopters:Paradise Helicopters - Agency | AG13: =VLOOKUP(AH13,Target_IES!$A:$A,1,FALSE) -> Paradise Helicopters - Agency | AH13: Paradise Helicopters - Agency | AI13: Paradise Helicopters - Agency | AJ13: TRUE | AK13: 002051c503305d0c464d83b6c00d02ea997d67 | AL13: 8 | AM13: Net 30 | AN13: 99 | AO13: paradise.helicopters@bills.corpayone.com | AP13: [NULL] | AQ13: 593695 | AR13: [NULL] | AS13: [NULL] | AT13: [NULL] | AU13: Paradise Helicopters - Agency | AV13: 808-969-7392 | AW13: [NULL] | AX13: [NULL] | AY13: 107 | AZ13: 1 | BA13: [NULL] | BB13: [NULL] | BC13: [NULL] | BD13: [NULL] | BE13: [NULL] | BF13: [NULL] | BG13: [NULL] | BH13: [NULL]
A14: FALSE | B14: 79 | C14: Hyve Solutions | D14: Attn Stacey Duncan | E14: 44201 Nobel Dr. | F14: Fremont | G14: CA | H14: 94538 | I14: 79 | J14: Hyve Solutions | K14: Attn Stacey Duncan | L14: 44201 Nobel Dr. | M14: Fremont | N14: CA | O14: 94538 | P14: TRUE | Q14: TRUE | R14: 0 | S14: 0 | T14: USD | U14: United States Dollar | V14: Print | W14: TRUE | X14: 0 | Y14: QBO | Z14: FALSE | AA14: 138 | AC14: 3 | AD14: 2024-12-03T16:39:52-08:00 | AE14: 2025-04-03T17:59:41-07:00 | AF14: Direct:Rockit Events | AG14: =VLOOKUP(AH14,Target_IES!$A:$A,1,FALSE) -> Rockit Events | AH14: Rockit Events | AI14: Rockit Events | AJ14: TRUE | AK14: 002051e01f3ea5d2174c33b40bce020435820e | AL14: [NULL] | AM14: [NULL] | AN14: 99 | AO14: [NULL] | AP14: [NULL] | AQ14: 593697 | AR14: [NULL] | AS14: [NULL] | AT14: [NULL] | AU14: [NULL] | AV14: [NULL] | AW14: [NULL] | AX14: [NULL] | AY14: 131 | AZ14: 1 | BA14: [NULL] | BB14: [NULL] | BC14: [NULL] | BD14: [NULL] | BE14: [NULL] | BF14: [NULL] | BG14: [NULL] | BH14: [NULL]
A15: FALSE | B15: [NULL] | C15: [NULL] | D15: [NULL] | E15: [NULL] | F15: [NULL] | G15: [NULL] | H15: [NULL] | I15: [NULL] | J15: [NULL] | K15: [NULL] | L15: [NULL] | M15: [NULL] | N15: [NULL] | O15: [NULL] | P15: TRUE | Q15: TRUE | R15: 0 | S15: 0 | T15: USD | U15: United States Dollar | V15: Print | W15: TRUE | X15: 0 | Y15: QBO | Z15: FALSE | AA15: 137 | AC15: 5 | AD15: 2024-12-03T16:39:52-08:00 | AE15: 2025-04-08T18:25:50-07:00 | AF15: Direct:DoTerra | AG15: =VLOOKUP(AH15,Target_IES!$A:$A,1,FALSE) -> DoTerra | AH15: DoTerra | AI15: DoTerra | AJ15: TRUE | AK15: 002051c22a4d77d6e64ae480d5a25b91fa0d97 | AL15: [NULL] | AM15: [NULL] | AN15: 99 | AO15: groups@hawaii-forest.com | AP15: [NULL] | AQ15: 593697 | AR15: [NULL] | AS15: [NULL] | AT15: [NULL] | AU15: [NULL] | AV15: [NULL] | AW15: [NULL] | AX15: [NULL] | AY15: 131 | AZ15: 1 | BA15: [NULL] | BB15: [NULL] | BC15: [NULL] | BD15: [NULL] | BE15: [NULL] | BF15: [NULL] | BG15: [NULL] | BH15: [NULL]
A16: FALSE | B16: [NULL] | C16: [NULL] | D16: [NULL] | E16: [NULL] | F16: [NULL] | G16: [NULL] | H16: [NULL] | I16: [NULL] | J16: [NULL] | K16: [NULL] | L16: [NULL] | M16: [NULL] | N16: [NULL] | O16: [NULL] | P16: TRUE | Q16: TRUE | R16: 0 | S16: 0 | T16: USD | U16: United States Dollar | V16: Print | W16: TRUE | X16: 0 | Y16: QBO | Z16: FALSE | AA16: 135 | AC16: 3 | AD16: 2024-12-03T16:39:52-08:00 | AE16: 2025-04-03T17:58:22-07:00 | AF16: Direct:Affiliate 20% | AG16: =VLOOKUP(AH16,Target_IES!$A:$A,1,FALSE) -> Affiliate 20% | AH16: Affiliate 20% | AI16: Affiliate 20% | AJ16: TRUE | AK16: 0020515a2e8b3306bc41d483777ff25bdac575 | AL16: [NULL] | AM16: [NULL] | AN16: 99 | AO16: groups@hawaii-forest.com | AP16: [NULL] | AQ16: 593697 | AR16: [NULL] | AS16: [NULL] | AT16: [NULL] | AU16: [NULL] | AV16: [NULL] | AW16: [NULL] | AX16: [NULL] | AY16: 131 | AZ16: 1 | BA16: [NULL] | BB16: [NULL] | BC16: [NULL] | BD16: [NULL] | BE16: [NULL] | BF16: [NULL] | BG16: [NULL] | BH16: [NULL]
A17: FALSE | B17: 76 | C17: 2525 Wallingwood Drive | D17: Ste 1003 | E17: [NULL] | F17: Austin | G17: TX | H17: 78746 | I17: 76 | J17: 2525 Wallingwood Drive | K17: Ste 1003 | L17: [NULL] | M17: Austin | N17: TX | O17: 78746 | P17: TRUE | Q17: TRUE | R17: 0 | S17: 0 | T17: USD | U17: United States Dollar | V17: Print | W17: TRUE | X17: 0 | Y17: QBO | Z17: FALSE | AA17: 132 | AC17: 10 | AD17: 2024-12-03T16:39:52-08:00 | AE17: 2025-06-18T19:00:25-07:00 | AF17: Direct:Victor Emanuel Nature Tours | AG17: =VLOOKUP(AH17,Target_IES!$A:$A,1,FALSE) -> Victor Emanuel Nature Tours | AH17: Victor Emanuel Nature Tours | AI17: Victor Emanuel Nature Tours | AJ17: TRUE | AK17: 0020512913596dc810456f8f77b2680f03f497 | AL17: [NULL] | AM17: [NULL] | AN17: 99 | AO17: celeste@ventbird.com | AP17: [NULL] | AQ17: 593697 | AR17: [NULL] | AS17: [NULL] | AT17: [NULL] | AU17: [NULL] | AV17: [NULL] | AW17: [NULL] | AX17: [NULL] | AY17: 131 | AZ17: 1 | BA17: [NULL] | BB17: [NULL] | BC17: [NULL] | BD17: [NULL] | BE17: [NULL] | BF17: [NULL] | BG17: [NULL] | BH17: [NULL]
A18: FALSE | B18: [NULL] | C18: [NULL] | D18: [NULL] | E18: [NULL] | F18: [NULL] | G18: [NULL] | H18: [NULL] | I18: [NULL] | J18: [NULL] | K18: [NULL] | L18: [NULL] | M18: [NULL] | N18: [NULL] | O18: [NULL] | P18: TRUE | Q18: TRUE | R18: 0 | S18: 0 | T18: USD | U18: United States Dollar | V18: Print | W18: TRUE | X18: 0 | Y18: QBO | Z18: FALSE | AA18: 141 | AC18: 3 | AD18: 2024-12-03T16:39:53-08:00 | AE18: 2025-04-03T17:59:56-07:00 | AF18: Direct:Frosch Travel | AG18: =VLOOKUP(AH18,Target_IES!$A:$A,1,FALSE) -> Frosch Travel | AH18: Frosch Travel | AI18: Frosch Travel | AJ18: TRUE | AK18: 002051bd39c608f29941aab2c5aacd744f0517 | AL18: [NULL] | AM18: [NULL] | AN18: 99 | AO18: [NULL] | AP18: [NULL] | AQ18: 593697 | AR18: [NULL] | AS18: [NULL] | AT18: [NULL] | AU18: [NULL] | AV18: [NULL] | AW18: [NULL] | AX18: [NULL] | AY18: 131 | AZ18: 1 | BA18: [NULL] | BB18: [NULL] | BC18: [NULL] | BD18: [NULL] | BE18: [NULL] | BF18: [NULL] | BG18: [NULL] | BH18: [NULL]
A19: FALSE | B19: [NULL] | C19: [NULL] | D19: [NULL] | E19: [NULL] | F19: [NULL] | G19: [NULL] | H19: [NULL] | I19: [NULL] | J19: [NULL] | K19: [NULL] | L19: [NULL] | M19: [NULL] | N19: [NULL] | O19: [NULL] | P19: TRUE | Q19: TRUE | R19: 0 | S19: 0 | T19: USD | U19: United States Dollar | V19: Print | W19: TRUE | X19: 0 | Y19: QBO | Z19: FALSE | AA19: 140 | AC19: 3 | AD19: 2024-12-03T16:39:53-08:00 | AE19: 2025-04-03T17:59:49-07:00 | AF19: Direct:Going Places Travel | AG19: =VLOOKUP(AH19,Target_IES!$A:$A,1,FALSE) -> Going Places Travel | AH19: Going Places Travel | AI19: Going Places Travel | AJ19: TRUE | AK19: 002051613ad3316f6e4de3a031eab16c2988ae | AL19: [NULL] | AM19: [NULL] | AN19: 99 | AO19: [NULL] | AP19: [NULL] | AQ19: 593697 | AR19: [NULL] | AS19: [NULL] | AT19: [NULL] | AU19: [NULL] | AV19: [NULL] | AW19: [NULL] | AX19: [NULL] | AY19: 131 | AZ19: 1 | BA19: [NULL] | BB19: [NULL] | BC19: [NULL] | BD19: [NULL] | BE19: [NULL] | BF19: [NULL] | BG19: [NULL] | BH19: [NULL]
A20: FALSE | B20: 80 | C20: Direct | D20: [NULL] | E20: [NULL] | F20: [NULL] | G20: [NULL] | H20: [NULL] | I20: 80 | J20: Direct | K20: [NULL] | L20: [NULL] | M20: [NULL] | N20: [NULL] | O20: [NULL] | P20: TRUE | Q20: TRUE | R20: 0 | S20: 0 | T20: USD | U20: United States Dollar | V20: Print | W20: TRUE | X20: 0 | Y20: QBO | Z20: FALSE | AA20: 139 | AC20: 6 | AD20: 2024-12-03T16:39:53-08:00 | AE20: 2025-04-03T17:59:44-07:00 | AF20: Direct:The Wright Company:The Wright Company | AG20: =VLOOKUP(AH20,Target_IES!$A:$A,1,FALSE) -> The Wright Company | AH20: The Wright Company | AI20: The Wright Company | AJ20: TRUE | AK20: 002051b0d7754fb2db4d74b3a144aef7c51a79 | AL20: [NULL] | AM20: [NULL] | AN20: 99 | AO20: brandon.eisman@mfactormeetings.com | AP20: [NULL] | AQ20: [NULL] | AR20: [NULL] | AS20: [NULL] | AT20: [NULL] | AU20: [NULL] | AV20: [NULL] | AW20: [NULL] | AX20: [NULL] | AY20: 1155 | AZ20: 2 | BA20: [NULL] | BB20: [NULL] | BC20: [NULL] | BD20: [NULL] | BE20: [NULL] | BF20: [NULL] | BG20: [NULL] | BH20: [NULL]
A21: FALSE | B21: 94 | C21: Hualalai Investors, LLC, | D21: dba Four Seasons Resort Hualalai | E21: P.O. Box 1269 | F21: Kailua-Kona | G21: HI | H21: 96740 | I21: 94 | J21: Hualalai Investors, LLC, | K21: dba Four Seasons Resort Hualalai | L21: P.O. Box 1269 | M21: Kailua-Kona | N21: HI | O21: 96740 | P21: TRUE | Q21: TRUE | R21: 0 | S21: 0 | T21: USD | U21: United States Dollar | V21: Print | W21: TRUE | X21: 0 | Y21: QBO | Z21: FALSE | AA21: 161 | AB21: =_xlfn.CONCAT("'",AA21,"'",",") -> '161', | AC21: 3 | AD21: 2024-12-03T16:39:54-08:00 | AE21: 2025-04-03T17:59:14-07:00 | AF21: KFour Seasons:Four Seasons Hualalai | AG21: =VLOOKUP(AH21,Target_IES!$A:$A,1,FALSE) -> #N/A | AH21: Four Seasons Hualalai | AI21: Four Seasons Hualalai | AJ21: TRUE | AK21: 0020516190bc0eab59497689538cbe8ff12787 | AL21: 8 | AM21: Net 30 | AN21: 99 | AO21: james.cantyne@fourseasons.com | AP21: Jerry Hiraishi_x000D_ Accounts Payable_x000D_ Four Seasons Resort Hualalai_x000D_ 72-100 Ka'upulehu Drive _x000D_ Kailua Kona, HI 96740_x000D_ Voice: | AQ21: 593698 | AR21: [NULL] | AS21: [NULL] | AT21: [NULL] | AU21: Four Seasons | AV21: (808)325-8058 | AW21: (808)325-8094 | AX21: [NULL] | AY21: 160 | AZ21: 1 | BA21: [NULL] | BB21: [NULL] | BC21: [NULL] | BD21: [NULL] | BE21: [NULL] | BF21: [NULL] | BG21: [NULL] | BH21: [NULL]
A22: TRUE | B22: [NULL] | C22: [NULL] | D22: [NULL] | E22: [NULL] | F22: [NULL] | G22: [NULL] | H22: [NULL] | I22: [NULL] | J22: [NULL] | K22: [NULL] | L22: [NULL] | M22: [NULL] | N22: [NULL] | O22: [NULL] | P22: TRUE | Q22: TRUE | R22: 0 | S22: 0 | T22: USD | U22: United States Dollar | V22: Print | W22: TRUE | X22: 0 | Y22: QBO | Z22: FALSE | AA22: 199 | AB22: =_xlfn.CONCAT("'",AA22,"'",",") -> '199', | AC22: 2 | AD22: 2024-12-03T16:39:57-08:00 | AE22: 2025-04-03T17:59:37-07:00 | AF22: KOZI:KOZI Sales & Marketing Dept | AG22: =VLOOKUP(AH22,Target_IES!$A:$A,1,FALSE) -> #N/A | AH22: KOZI Sales & Marketing Dept | AI22: KOZI Sales & Marketing Dept | AJ22: TRUE | AK22: 002051ac965acfbacd4843bc8b3818f7c95191 | AL22: [NULL] | AM22: [NULL] | AN22: [NULL] | AO22: [NULL] | AP22: [NULL] | AQ22: [NULL] | AR22: [NULL] | AS22: [NULL] | AT22: [NULL] | AU22: [NULL] | AV22: [NULL] | AW22: [NULL] | AX22: [NULL] | AY22: 198 | AZ22: 1 | BA22: [NULL] | BB22: [NULL] | BC22: [NULL] | BD22: [NULL] | BE22: [NULL] | BF22: [NULL] | BG22: [NULL] | BH22: [NULL]
A23: FALSE | B23: [NULL] | C23: [NULL] | D23: [NULL] | E23: [NULL] | F23: [NULL] | G23: [NULL] | H23: [NULL] | I23: [NULL] | J23: [NULL] | K23: [NULL] | L23: [NULL] | M23: [NULL] | N23: [NULL] | O23: [NULL] | P23: TRUE | Q23: TRUE | R23: 0 | S23: 0 | T23: USD | U23: United States Dollar | V23: Print | W23: TRUE | X23: 0 | Y23: QBO | Z23: FALSE | AA23: 195 | AC23: 3 | AD23: 2024-12-03T16:39:57-08:00 | AE23: 2025-04-03T17:59:34-07:00 | AF23: KDirect:The Wright Company | AG23: =VLOOKUP(AH23,Target_IES!$A:$A,1,FALSE) -> The Wright Company | AH23: The Wright Company | AI23: The Wright Company | AJ23: TRUE | AK23: 0020510f709731e734431f97dd1d47ff77ba17 | AL23: 8 | AM23: Net 30 | AN23: 99 | AO23: brandon.eisman@mfactormeetings.com | AP23: [NULL] | AQ23: 593700 | AR23: [NULL] | AS23: [NULL] | AT23: [NULL] | AU23: [NULL] | AV23: [NULL] | AW23: [NULL] | AX23: PonoRez | AY23: 190 | AZ23: 1 | BA23: [NULL] | BB23: [NULL] | BC23: Online | BD23: [NULL] | BE23: [NULL] | BF23: [NULL] | BG23: [NULL] | BH23: [NULL]
A24: FALSE | B24: [NULL] | C24: [NULL] | D24: [NULL] | E24: [NULL] | F24: [NULL] | G24: [NULL] | H24: [NULL] | I24: [NULL] | J24: [NULL] | K24: [NULL] | L24: [NULL] | M24: [NULL] | N24: [NULL] | O24: [NULL] | P24: TRUE | Q24: TRUE | R24: 0 | S24: 0 | T24: USD | U24: United States Dollar | V24: Print | W24: TRUE | X24: 0 | Y24: QBO | Z24: FALSE | AA24: 194 | AC24: 5 | AD24: 2024-12-03T16:39:57-08:00 | AE24: 2025-04-03T17:59:37-07:00 | AF24: KDirect:kDirect RockIt Events:RockIt Events | AG24: =VLOOKUP(AH24,Target_IES!$A:$A,1,FALSE) -> Rockit Events | AH24: RockIt Events | AI24: RockIt Events | AJ24: TRUE | AK24: 002051383445cb1fd94c9cadf44d7b2434740e | AL24: 8 | AM24: Net 30 | AN24: 99 | AO24: brandon.eisman@mfactormeetings.com | AP24: [NULL] | AQ24: 593700 | AR24: [NULL] | AS24: [NULL] | AT24: [NULL] | AU24: [NULL] | AV24: [NULL] | AW24: [NULL] | AX24: PonoRez | AY24: 1154 | AZ24: 2 | BA24: [NULL] | BB24: [NULL] | BC24: Online | BD24: [NULL] | BE24: [NULL] | BF24: [NULL] | BG24: [NULL] | BH24: [NULL]
A25: FALSE | B25: [NULL] | C25: [NULL] | D25: [NULL] | E25: [NULL] | F25: [NULL] | G25: [NULL] | H25: [NULL] | I25: [NULL] | J25: [NULL] | K25: [NULL] | L25: [NULL] | M25: [NULL] | N25: [NULL] | O25: [NULL] | P25: TRUE | Q25: TRUE | R25: 0 | S25: 0 | T25: USD | U25: United States Dollar | V25: Print | W25: TRUE | X25: 0 | Y25: QBO | Z25: FALSE | AA25: 192 | AC25: 5 | AD25: 2024-12-03T16:39:57-08:00 | AE25: 2025-04-03T17:58:43-07:00 | AF25: KDirect:kDirect Crossing Boundaries:Crossing Boundaries | AG25: =VLOOKUP(AH25,Target_IES!$A:$A,1,FALSE) -> Crossing Boundaries | AH25: Crossing Boundaries | AI25: Crossing Boundaries | AJ25: TRUE | AK25: 00205169a26dbac5d348bba3f7583ecac4de00 | AL25: 8 | AM25: Net 30 | AN25: 99 | AO25: brandon.eisman@mfactormeetings.com | AP25: [NULL] | AQ25: 593700 | AR25: [NULL] | AS25: [NULL] | AT25: [NULL] | AU25: [NULL] | AV25: [NULL] | AW25: [NULL] | AX25: PonoRez | AY25: 1153 | AZ25: 2 | BA25: [NULL] | BB25: [NULL] | BC25: Online | BD25: [NULL] | BE25: [NULL] | BF25: [NULL] | BG25: [NULL] | BH25: [NULL]
A26: FALSE | B26: [NULL] | C26: [NULL] | D26: [NULL] | E26: [NULL] | F26: [NULL] | G26: [NULL] | H26: [NULL] | I26: [NULL] | J26: [NULL] | K26: [NULL] | L26: [NULL] | M26: [NULL] | N26: [NULL] | O26: [NULL] | P26: TRUE | Q26: TRUE | R26: 0 | S26: 0 | T26: USD | U26: United States Dollar | V26: Print | W26: TRUE | X26: 0 | Y26: QBO | Z26: FALSE | AA26: 191 | AC26: 5 | AD26: 2024-12-03T16:39:57-08:00 | AE26: 2025-04-03T17:58:17-07:00 | AF26: KDirect:KAffiliate 20%:Affiliate 20% | AG26: =VLOOKUP(AH26,Target_IES!$A:$A,1,FALSE) -> Affiliate 20% | AH26: Affiliate 20% | AI26: Affiliate 20% | AJ26: TRUE | AK26: 00205156adbf802b5c45acb1c37672e17c6174 | AL26: 8 | AM26: Net 30 | AN26: 99 | AO26: brandon.eisman@mfactormeetings.com | AP26: [NULL] | AQ26: 593700 | AR26: [NULL] | AS26: [NULL] | AT26: [NULL] | AU26: [NULL] | AV26: [NULL] | AW26: [NULL] | AX26: PonoRez | AY26: 1152 | AZ26: 2 | BA26: [NULL] | BB26: [NULL] | BC26: Online | BD26: [NULL] | BE26: [NULL] | BF26: [NULL] | BG26: [NULL] | BH26: [NULL]
A27: FALSE | B27: 132 | C27: 300 Ohukai Road, #315 | D27: [NULL] | E27: [NULL] | F27: Kihei | G27: HI | H27: 96753 | I27: 132 | J27: 300 Ohukai Road, #315 | K27: [NULL] | L27: [NULL] | M27: Kihei | N27: HI | O27: 96753 | P27: TRUE | Q27: TRUE | R27: 0 | S27: 0 | T27: USD | U27: United States Dollar | V27: Print | W27: TRUE | X27: 0 | Y27: QBO | Z27: FALSE | AA27: 299 | AC27: 3 | AD27: 2024-12-03T16:40:04-08:00 | AE27: 2025-04-03T17:58:36-07:00 | AF27: Chrysalis Events:Chrysalis Events Hawaii | AG27: =VLOOKUP(AH27,Target_IES!$A:$A,1,FALSE) -> Chrysalis Events Hawaii | AH27: Chrysalis Events Hawaii | AI27: Chrysalis Events Hawaii | AJ27: TRUE | AK27: 002051667d77da4b414bf7b888e3c7d692f309 | AL27: 8 | AM27: Net 30 | AN27: 99 | AO27: billing@chrysaliseventshawaii.com | AP27: [NULL] | AQ27: 593694 | AR27: [NULL] | AS27: [NULL] | AT27: [NULL] | AU27: [NULL] | AV27: 808-419-6816 | AW27: 808-440-4526 | AX27: [NULL] | AY27: 86 | AZ27: 1 | BA27: [NULL] | BB27: [NULL] | BC27: [NULL] | BD27: [NULL] | BE27: [NULL] | BF27: [NULL] | BG27: [NULL] | BH27: [NULL]
A28: FALSE | B28: [NULL] | C28: [NULL] | D28: [NULL] | E28: [NULL] | F28: [NULL] | G28: [NULL] | H28: [NULL] | I28: [NULL] | J28: [NULL] | K28: [NULL] | L28: [NULL] | M28: [NULL] | N28: [NULL] | O28: [NULL] | P28: TRUE | Q28: TRUE | R28: 0 | S28: 0 | T28: USD | U28: United States Dollar | V28: Print | W28: TRUE | X28: 0 | Y28: QBO | Z28: FALSE | AA28: 297 | AC28: 3 | AD28: 2024-12-03T16:40:04-08:00 | AE28: 2025-04-03T17:58:30-07:00 | AF28: Chrysalis Events:Chrysalis Event Hawaii - FIT | AG28: =VLOOKUP(AH28,Target_IES!$A:$A,1,FALSE) -> Chrysalis Event Hawaii - FIT | AH28: Chrysalis Event Hawaii - FIT | AI28: Chrysalis Event Hawaii - FIT | AJ28: TRUE | AK28: 002051b3a16f6dbf1d4d31af3d37a46a484c90 | AL28: 8 | AM28: Net 30 | AN28: 99 | AO28: billing@chrysaliseventshawaii.com | AP28: [NULL] | AQ28: 593695 | AR28: [NULL] | AS28: [NULL] | AT28: [NULL] | AU28: [NULL] | AV28: [NULL] | AW28: [NULL] | AX28: [NULL] | AY28: 86 | AZ28: 1 | BA28: [NULL] | BB28: [NULL] | BC28: [NULL] | BD28: [NULL] | BE28: [NULL] | BF28: [NULL] | BG28: [NULL] | BH28: [NULL]
A29: FALSE | B29: [NULL] | C29: [NULL] | D29: [NULL] | E29: [NULL] | F29: [NULL] | G29: [NULL] | H29: [NULL] | I29: [NULL] | J29: [NULL] | K29: [NULL] | L29: [NULL] | M29: [NULL] | N29: [NULL] | O29: [NULL] | P29: TRUE | Q29: TRUE | R29: 0 | S29: 0 | T29: USD | U29: United States Dollar | V29: Print | W29: TRUE | X29: 0 | Y29: QBO | Z29: FALSE | AA29: 1169 | AB29: =_xlfn.CONCAT("'",AA29,"'",",") -> '1169', | AC29: 10 | AD29: 2024-12-13T14:03:47-08:00 | AE29: 2025-04-08T18:25:52-07:00 | AF29: Direct:Affiliate 20%D:UGA | AG29: =VLOOKUP(AH29,Target_IES!$A:$A,1,FALSE) -> #N/A | AH29: UGA | AI29: UGA | AJ29: TRUE | AK29: 002051be411b0781564eaeaf1659c9792ee59d | AL29: [NULL] | AM29: [NULL] | AN29: 99 | AO29: groups@hawaii-forest.com | AP29: [NULL] | AQ29: 593697 | AR29: [NULL] | AS29: [NULL] | AT29: [NULL] | AU29: [NULL] | AV29: [NULL] | AW29: [NULL] | AX29: [NULL] | AY29: 1159 | AZ29: 2 | BA29: [NULL] | BB29: [NULL] | BC29: [NULL] | BD29: [NULL] | BE29: [NULL] | BF29: [NULL] | BG29: [NULL] | BH29: [NULL]
A30: TRUE | B30: [NULL] | C30: [NULL] | D30: [NULL] | E30: [NULL] | F30: [NULL] | G30: [NULL] | H30: [NULL] | I30: [NULL] | J30: [NULL] | K30: [NULL] | L30: [NULL] | M30: [NULL] | N30: [NULL] | O30: [NULL] | P30: TRUE | Q30: TRUE | R30: 0 | S30: 0 | T30: USD | U30: United States Dollar | V30: Print | W30: TRUE | X30: 0 | Y30: QBO | Z30: FALSE | AA30: 1173 | AC30: 2 | AD30: 2024-12-19T18:28:57-08:00 | AE30: 2025-04-02T13:11:37-07:00 | AF30: Direct:Resilient Indigenous Leaders Network | AG30: =VLOOKUP(AH30,Target_IES!$A:$A,1,FALSE) -> Resilient Indigenous Leaders Network | AH30: Resilient Indigenous Leaders Network | AI30: Resilient Indigenous Leaders Network | AJ30: TRUE | AK30: 002051e5d55eac493a46aa901a7f43a32b7ab9 | AL30: [NULL] | AM30: [NULL] | AN30: [NULL] | AO30: stephanie.lynn.puleo@gmail.com, groups@hawaii-forest.com | AP30: [NULL] | AQ30: 593697 | AR30: [NULL] | AS30: [NULL] | AT30: [NULL] | AU30: [NULL] | AV30: [NULL] | AW30: [NULL] | AX30: [NULL] | AY30: 131 | AZ30: 1 | BA30: [NULL] | BB30: [NULL] | BC30: [NULL] | BD30: [NULL] | BE30: [NULL] | BF30: [NULL] | BG30: [NULL] | BH30: [NULL]
A31: TRUE | B31: [NULL] | C31: [NULL] | D31: [NULL] | E31: [NULL] | F31: [NULL] | G31: [NULL] | H31: [NULL] | I31: [NULL] | J31: [NULL] | K31: [NULL] | L31: [NULL] | M31: [NULL] | N31: [NULL] | O31: [NULL] | P31: TRUE | Q31: TRUE | R31: 0 | S31: 0 | T31: USD | U31: United States Dollar | V31: Print | W31: TRUE | X31: 0 | Y31: QBO | Z31: FALSE | AA31: 1243 | AB31: =_xlfn.CONCAT("'",AA31,"'",",") -> '1243', | AC31: 2 | AD31: 2025-02-12T17:58:01-08:00 | AE31: 2025-04-02T13:11:07-07:00 | AF31: Direct:Eagle Eye Tours | AG31: =VLOOKUP(AH31,Target_IES!$A:$A,1,FALSE) -> #N/A | AH31: Eagle Eye Tours | AI31: Eagle Eye Tours | AJ31: TRUE | AK31: 0020513d02b28904c644a2acaa687f29d892a7 | AL31: [NULL] | AM31: [NULL] | AN31: [NULL] | AO31: juliana@eagle-eye.com | AP31: [NULL] | AQ31: 593697 | AR31: [NULL] | AS31: [NULL] | AT31: [NULL] | AU31: [NULL] | AV31: [NULL] | AW31: [NULL] | AX31: [NULL] | AY31: 131 | AZ31: 1 | BA31: [NULL] | BB31: [NULL] | BC31: [NULL] | BD31: [NULL] | BE31: [NULL] | BF31: [NULL] | BG31: [NULL] | BH31: [NULL]
A32: TRUE | B32: [NULL] | C32: [NULL] | D32: [NULL] | E32: [NULL] | F32: [NULL] | G32: [NULL] | H32: [NULL] | I32: [NULL] | J32: [NULL] | K32: [NULL] | L32: [NULL] | M32: [NULL] | N32: [NULL] | O32: [NULL] | P32: TRUE | Q32: TRUE | R32: 0 | S32: 0 | T32: USD | U32: United States Dollar | V32: Print | W32: TRUE | X32: 0 | Y32: QBO | Z32: FALSE | AA32: 1299 | AB32: =_xlfn.CONCAT("'",AA32,"'",",") -> '1299', | AC32: 3 | AD32: 2025-04-21T18:54:36-07:00 | AE32: 2025-05-16T17:35:07-07:00 | AF32: KMC&A:KMC&A Groups:Cetera | AG32: =VLOOKUP(AH32,Target_IES!$A:$A,1,FALSE) -> #N/A | AH32: Cetera | AI32: Cetera | AJ32: TRUE | AK32: 0020510967b68348b147ffbea19733a201427c | AL32: [NULL] | AM32: [NULL] | AN32: [NULL] | AO32: accountingmca@mcahawaii.com | AP32: [NULL] | AQ32: [NULL] | AR32: [NULL] | AS32: [NULL] | AT32: [NULL] | AU32: [NULL] | AV32: [NULL] | AW32: [NULL] | AX32: [NULL] | AY32: 1279 | AZ32: 2 | BA32: [NULL] | BB32: [NULL] | BC32: [NULL] | BD32: [NULL] | BE32: [NULL] | BF32: [NULL] | BG32: [NULL] | BH32: [NULL]
A33: TRUE | B33: [NULL] | C33: [NULL] | D33: [NULL] | E33: [NULL] | F33: [NULL] | G33: [NULL] | H33: [NULL] | I33: [NULL] | J33: [NULL] | K33: [NULL] | L33: [NULL] | M33: [NULL] | N33: [NULL] | O33: [NULL] | P33: TRUE | Q33: TRUE | R33: 0 | S33: 0 | T33: USD | U33: United States Dollar | V33: Print | W33: TRUE | X33: 0 | Y33: QBO | Z33: FALSE | AA33: 1303 | AB33: =_xlfn.CONCAT("'",AA33,"'",",") -> '1303', | AC33: 2 | AD33: 2025-04-25T12:46:20-07:00 | AE33: 2025-07-22T18:56:02-07:00 | AF33: MC&A:MC&A - Groups:Sentinel One HFT | AG33: =VLOOKUP(AH33,Target_IES!$A:$A,1,FALSE) -> #N/A | AH33: Sentinel One HFT | AI33: Sentinel One HFT | AJ33: TRUE | AK33: 0020514c8b985c712e401fa3a9b5ebb71e9ed6 | AL33: [NULL] | AM33: [NULL] | AN33: [NULL] | AO33: accountingmca@mcahawaii.com | AP33: [NULL] | AQ33: [NULL] | AR33: [NULL] | AS33: [NULL] | AT33: [NULL] | AU33: [NULL] | AV33: [NULL] | AW33: [NULL] | AX33: [NULL] | AY33: 1185 | AZ33: 2 | BA33: [NULL] | BB33: [NULL] | BC33: [NULL] | BD33: [NULL] | BE33: [NULL] | BF33: [NULL] | BG33: [NULL] | BH33: [NULL]
A34: TRUE | B34: [NULL] | C34: [NULL] | D34: [NULL] | E34: [NULL] | F34: [NULL] | G34: [NULL] | H34: [NULL] | I34: [NULL] | J34: [NULL] | K34: [NULL] | L34: [NULL] | M34: [NULL] | N34: [NULL] | O34: [NULL] | P34: TRUE | Q34: TRUE | R34: 0 | S34: 0 | T34: USD | U34: United States Dollar | V34: Print | W34: TRUE | X34: 0 | Y34: QBO | Z34: FALSE | AA34: 1304 | AB34: =_xlfn.CONCAT("'",AA34,"'",",") -> '1304', | AC34: 1 | AD34: 2025-04-25T13:06:52-07:00 | AE34: 2025-07-07T18:36:53-07:00 | AF34: MC&A:MC&A - Groups:Sentinel One KOZI | AG34: =VLOOKUP(AH34,Target_IES!$A:$A,1,FALSE) -> #N/A | AH34: Sentinel One KOZI | AI34: Sentinel One KOZI | AJ34: TRUE | AK34: 0020511ec481744c5041eea8656b0d7d9a34d3 | AL34: [NULL] | AM34: [NULL] | AN34: [NULL] | AO34: accountingmca@mcahawaii.com | AP34: [NULL] | AQ34: [NULL] | AR34: [NULL] | AS34: [NULL] | AT34: [NULL] | AU34: [NULL] | AV34: [NULL] | AW34: [NULL] | AX34: [NULL] | AY34: 1185 | AZ34: 2 | BA34: [NULL] | BB34: [NULL] | BC34: [NULL] | BD34: [NULL] | BE34: [NULL] | BF34: [NULL] | BG34: [NULL] | BH34: [NULL]
A35: TRUE | B35: [NULL] | C35: [NULL] | D35: [NULL] | E35: [NULL] | F35: [NULL] | G35: [NULL] | H35: [NULL] | I35: [NULL] | J35: [NULL] | K35: [NULL] | L35: [NULL] | M35: [NULL] | N35: [NULL] | O35: [NULL] | P35: TRUE | Q35: TRUE | R35: 0 | S35: 0 | T35: USD | U35: United States Dollar | V35: Print | W35: TRUE | X35: 0 | Y35: QBO | Z35: FALSE | AA35: 1305 | AB35: =_xlfn.CONCAT("'",AA35,"'",",") -> '1305', | AC35: 1 | AD35: 2025-04-25T16:27:45-07:00 | AE35: 2025-04-25T16:29:22-07:00 | AF35: MC&A:MC&A - Groups:Otsuka HFT | AG35: =VLOOKUP(AH35,Target_IES!$A:$A,1,FALSE) -> #N/A | AH35: Otsuka HFT | AI35: Otsuka HFT | AJ35: TRUE | AK35: 0020514af7d92362ef4b85b83f662126b14a23 | AL35: [NULL] | AM35: [NULL] | AN35: [NULL] | AO35: [NULL] | AP35: [NULL] | AQ35: [NULL] | AR35: [NULL] | AS35: [NULL] | AT35: [NULL] | AU35: [NULL] | AV35: [NULL] | AW35: [NULL] | AX35: [NULL] | AY35: 1185 | AZ35: 2 | BA35: [NULL] | BB35: [NULL] | BC35: [NULL] | BD35: [NULL] | BE35: [NULL] | BF35: [NULL] | BG35: [NULL] | BH35: [NULL]
A36: TRUE | B36: [NULL] | C36: [NULL] | D36: [NULL] | E36: [NULL] | F36: [NULL] | G36: [NULL] | H36: [NULL] | I36: [NULL] | J36: [NULL] | K36: [NULL] | L36: [NULL] | M36: [NULL] | N36: [NULL] | O36: [NULL] | P36: TRUE | Q36: TRUE | R36: 0 | S36: 0 | T36: USD | U36: United States Dollar | V36: Print | W36: TRUE | X36: 0 | Y36: QBO | Z36: FALSE | AA36: 1306 | AB36: =_xlfn.CONCAT("'",AA36,"'",",") -> '1306', | AC36: 1 | AD36: 2025-04-25T17:32:52-07:00 | AE36: 2025-06-05T12:28:24-07:00 | AF36: Chrysalis Events:25-LNH611 | AG36: =VLOOKUP(AH36,Target_IES!$A:$A,1,FALSE) -> #N/A | AH36: 25-LNH611 | AI36: 25-LNH611 | AJ36: TRUE | AK36: 002051edc49c067d614c718b827717c32b98ef | AL36: [NULL] | AM36: [NULL] | AN36: [NULL] | AO36: billing@chrysaliseventshawaii.com | AP36: [NULL] | AQ36: [NULL] | AR36: [NULL] | AS36: [NULL] | AT36: [NULL] | AU36: [NULL] | AV36: [NULL] | AW36: [NULL] | AX36: [NULL] | AY36: 86 | AZ36: 1 | BA36: [NULL] | BB36: [NULL] | BC36: [NULL] | BD36: [NULL] | BE36: [NULL] | BF36: [NULL] | BG36: [NULL] | BH36: [NULL]
A37: TRUE | B37: [NULL] | C37: [NULL] | D37: [NULL] | E37: [NULL] | F37: [NULL] | G37: [NULL] | H37: [NULL] | I37: [NULL] | J37: [NULL] | K37: [NULL] | L37: [NULL] | M37: [NULL] | N37: [NULL] | O37: [NULL] | P37: TRUE | Q37: TRUE | R37: 0 | S37: 0 | T37: USD | U37: United States Dollar | V37: Print | W37: TRUE | X37: 0 | Y37: QBO | Z37: FALSE | AA37: 1307 | AB37: =_xlfn.CONCAT("'",AA37,"'",",") -> '1307', | AC37: 1 | AD37: 2025-04-25T17:49:45-07:00 | AE37: 2025-06-05T12:27:39-07:00 | AF37: KChrysalis Events Hawaii:25-LNH611KOZI | AG37: =VLOOKUP(AH37,Target_IES!$A:$A,1,FALSE) -> #N/A | AH37: 25-LNH611KOZI | AI37: 25-LNH611KOZI | AJ37: TRUE | AK37: 002051dc91035d5c554378887697fae311dcaa | AL37: [NULL] | AM37: [NULL] | AN37: [NULL] | AO37: billing@chrysaliseventshawaii.com | AP37: [NULL] | AQ37: 593694 | AR37: [NULL] | AS37: [NULL] | AT37: [NULL] | AU37: [NULL] | AV37: [NULL] | AW37: [NULL] | AX37: [NULL] | AY37: 154 | AZ37: 1 | BA37: [NULL] | BB37: [NULL] | BC37: [NULL] | BD37: [NULL] | BE37: [NULL] | BF37: [NULL] | BG37: [NULL] | BH37: [NULL]
A38: TRUE | B38: [NULL] | C38: [NULL] | D38: [NULL] | E38: [NULL] | F38: [NULL] | G38: [NULL] | H38: [NULL] | I38: [NULL] | J38: [NULL] | K38: [NULL] | L38: [NULL] | M38: [NULL] | N38: [NULL] | O38: [NULL] | P38: TRUE | Q38: TRUE | R38: 0 | S38: 0 | T38: USD | U38: United States Dollar | V38: Print | W38: TRUE | X38: 0 | Y38: QBO | Z38: FALSE | AA38: 1309 | AB38: =_xlfn.CONCAT("'",AA38,"'",",") -> '1309', | AC38: 1 | AD38: 2025-04-30T14:44:22-07:00 | AE38: 2025-07-18T14:09:43-07:00 | AF38: MC&A:Delinea | AG38: =VLOOKUP(AH38,Target_IES!$A:$A,1,FALSE) -> #N/A | AH38: Delinea | AI38: Delinea | AJ38: TRUE | AK38: 002051b25b3cee8bd8491b8479006ea6d28fe9 | AL38: [NULL] | AM38: [NULL] | AN38: [NULL] | AO38: accountingmca@mcahawaii.com | AP38: [NULL] | AQ38: [NULL] | AR38: [NULL] | AS38: [NULL] | AT38: [NULL] | AU38: [NULL] | AV38: [NULL] | AW38: [NULL] | AX38: [NULL] | AY38: 94 | AZ38: 1 | BA38: [NULL] | BB38: [NULL] | BC38: [NULL] | BD38: [NULL] | BE38: [NULL] | BF38: [NULL] | BG38: [NULL] | BH38: [NULL]
A39: TRUE | B39: [NULL] | C39: [NULL] | D39: [NULL] | E39: [NULL] | F39: [NULL] | G39: [NULL] | H39: [NULL] | I39: [NULL] | J39: [NULL] | K39: [NULL] | L39: [NULL] | M39: [NULL] | N39: [NULL] | O39: [NULL] | P39: TRUE | Q39: TRUE | R39: 0 | S39: 0 | T39: USD | U39: United States Dollar | V39: Print | W39: TRUE | X39: 0 | Y39: QBO | Z39: FALSE | AA39: 1320 | AB39: =_xlfn.CONCAT("'",AA39,"'",",") -> '1320', | AC39: 1 | AD39: 2025-05-20T19:20:58-07:00 | AE39: 2025-06-10T17:45:27-07:00 | AF39: Direct:Polynesian Adventures | AG39: =VLOOKUP(AH39,Target_IES!$A:$A,1,FALSE) -> #N/A | AH39: Polynesian Adventures | AI39: Polynesian Adventures | AJ39: TRUE | AK39: 002051507c1c9a71574448bda88f1fce15b38e | AL39: [NULL] | AM39: [NULL] | AN39: [NULL] | AO39: kelly@polyad.com | AP39: [NULL] | AQ39: 593697 | AR39: [NULL] | AS39: [NULL] | AT39: [NULL] | AU39: [NULL] | AV39: [NULL] | AW39: [NULL] | AX39: [NULL] | AY39: 131 | AZ39: 1 | BA39: [NULL] | BB39: [NULL] | BC39: [NULL] | BD39: [NULL] | BE39: [NULL] | BF39: [NULL] | BG39: [NULL] | BH39: [NULL]
A40: TRUE | B40: [NULL] | C40: [NULL] | D40: [NULL] | E40: [NULL] | F40: [NULL] | G40: [NULL] | H40: [NULL] | I40: [NULL] | J40: [NULL] | K40: [NULL] | L40: [NULL] | M40: [NULL] | N40: [NULL] | O40: [NULL] | P40: TRUE | Q40: TRUE | R40: 0 | S40: 0 | T40: USD | U40: United States Dollar | V40: Print | W40: TRUE | X40: 0 | Y40: QBO | Z40: FALSE | AA40: 1321 | AB40: =_xlfn.CONCAT("'",AA40,"'",",") -> '1321', | AC40: 2 | AD40: 2025-05-21T13:26:26-07:00 | AE40: 2025-06-05T18:02:49-07:00 | AF40: Direct:Companion Life | AG40: =VLOOKUP(AH40,Target_IES!$A:$A,1,FALSE) -> #N/A | AH40: Companion Life | AI40: Companion Life | AJ40: TRUE | AK40: 002051e9ff69a556fd4ee4abfb9e6afbb0263a | AL40: [NULL] | AM40: [NULL] | AN40: [NULL] | AO40: lora@exclusiveeme.com | AP40: [NULL] | AQ40: 593697 | AR40: [NULL] | AS40: [NULL] | AT40: [NULL] | AU40: [NULL] | AV40: [NULL] | AW40: [NULL] | AX40: [NULL] | AY40: 131 | AZ40: 1 | BA40: [NULL] | BB40: [NULL] | BC40: [NULL] | BD40: [NULL] | BE40: [NULL] | BF40: [NULL] | BG40: [NULL] | BH40: [NULL]
...
